Workbook

Sheet Dashboard
A1: OSSPolicyGuard — Requirements Tracker
A3: Product | B3: OSSPolicyGuard v0.1.0
A4: Product Leads | B4: Surya Nalluri · Aluri
A5: Last Updated | B5: August 2026
A7: PROGRESS OVERVIEW
A8: Metric | B8: Count | C8: % Total
A9: Total Requirements | B9: =COUNTA(Requirements!A2:A158)
A10: Done | B10: =COUNTIF(Requirements!G:G,"Done") | C10: =IF(C9>0,C10/C9,0)
A11: In Progress | B11: =COUNTIF(Requirements!G:G,"In Progress") | C11: =IF(C9>0,C11/C9,0)
A12: Not Started | B12: =COUNTIF(Requirements!G:G,"Not Started") | C12: =IF(C9>0,C12/C9,0)
A13: Blocked | B13: =COUNTIF(Requirements!G:G,"Blocked") | C13: =IF(C9>0,C13/C9,0)
A14: % Complete | B14: =IF(C9>0,C10/C9,0)
A16: PRIORITY BREAKDOWN
A17: P0 (Critical) | B17: =COUNTIF(Requirements!F:F,"P0") | C17: =IF($C$9>0,C17/$C$9,0)
A18: P1 (High) | B18: =COUNTIF(Requirements!F:F,"P1") | C18: =IF($C$9>0,C18/$C$9,0)
A19: P2 (Future) | B19: =COUNTIF(Requirements!F:F,"P2") | C19: =IF($C$9>0,C19/$C$9,0)
A21: WORKSTREAM SUMMARY
A22: Workstream | B22: Total | C22: Done | D22: In Progress | E22: Not Started | F22: Blocked
A23: WS 1: Architecture & Foundation | B23: =COUNTIF(Requirements!B:B,"1") | C23: =COUNTIFS(Requirements!B:B,"1",Requirements!G:G,"Done") | D23: =COUNTIFS(Requirements!B:B,"1",Requirements!G:G,"In Progress") | E23: =COUNTIFS(Requirements!B:B,"1",Requirements!G:G,"Not Started") | F23: =COUNTIFS(Requirements!B:B,"1",Requirements!G:G,"Blocked")
A24: WS 2: Identity & Dependency Ingestion | B24: =COUNTIF(Requirements!B:B,"2") | C24: =COUNTIFS(Requirements!B:B,"2",Requirements!G:G,"Done") | D24: =COUNTIFS(Requirements!B:B,"2",Requirements!G:G,"In Progress") | E24: =COUNTIFS(Requirements!B:B,"2",Requirements!G:G,"Not Started") | F24: =COUNTIFS(Requirements!B:B,"2",Requirements!G:G,"Blocked")
A25: WS 3: Evidence Providers & Data Quality | B25: =COUNTIF(Requirements!B:B,"3") | C25: =COUNTIFS(Requirements!B:B,"3",Requirements!G:G,"Done") | D25: =COUNTIFS(Requirements!B:B,"3",Requirements!G:G,"In Progress") | E25: =COUNTIFS(Requirements!B:B,"3",Requirements!G:G,"Not Started") | F25: =COUNTIFS(Requirements!B:B,"3",Requirements!G:G,"Blocked")
A26: WS 4: Vulnerability & Exploitability | B26: =COUNTIF(Requirements!B:B,"4") | C26: =COUNTIFS(Requirements!B:B,"4",Requirements!G:G,"Done") | D26: =COUNTIFS(Requirements!B:B,"4",Requirements!G:G,"In Progress") | E26: =COUNTIFS(Requirements!B:B,"4",Requirements!G:G,"Not Started") | F26: =COUNTIFS(Requirements!B:B,"4",Requirements!G:G,"Blocked")
A27: WS 5: Supply Chain & Malicious Package Defense | B27: =COUNTIF(Requirements!B:B,"5") | C27: =COUNTIFS(Requirements!B:B,"5",Requirements!G:G,"Done") | D27: =COUNTIFS(Requirements!B:B,"5",Requirements!G:G,"In Progress") | E27: =COUNTIFS(Requirements!B:B,"5",Requirements!G:G,"Not Started") | F27: =COUNTIFS(Requirements!B:B,"5",Requirements!G:G,"Blocked")
A28: WS 6: Policy Engine & Explainability | B28: =COUNTIF(Requirements!B:B,"6") | C28: =COUNTIFS(Requirements!B:B,"6",Requirements!G:G,"Done") | D28: =COUNTIFS(Requirements!B:B,"6",Requirements!G:G,"In Progress") | E28: =COUNTIFS(Requirements!B:B,"6",Requirements!G:G,"Not Started") | F28: =COUNTIFS(Requirements!B:B,"6",Requirements!G:G,"Blocked")
A29: WS 7: Outputs APIs & Developer Integrations | B29: =COUNTIF(Requirements!B:B,"7") | C29: =COUNTIFS(Requirements!B:B,"7",Requirements!G:G,"Done") | D29: =COUNTIFS(Requirements!B:B,"7",Requirements!G:G,"In Progress") | E29: =COUNTIFS(Requirements!B:B,"7",Requirements!G:G,"Not Started") | F29: =COUNTIFS(Requirements!B:B,"7",Requirements!G:G,"Blocked")
A30: WS 8: Enterprise Governance & Exceptions | B30: =COUNTIF(Requirements!B:B,"8") | C30: =COUNTIFS(Requirements!B:B,"8",Requirements!G:G,"Done") | D30: =COUNTIFS(Requirements!B:B,"8",Requirements!G:G,"In Progress") | E30: =COUNTIFS(Requirements!B:B,"8",Requirements!G:G,"Not Started") | F30: =COUNTIFS(Requirements!B:B,"8",Requirements!G:G,"Blocked")
A31: WS 9: Security Privacy & Reliability | B31: =COUNTIF(Requirements!B:B,"9") | C31: =COUNTIFS(Requirements!B:B,"9",Requirements!G:G,"Done") | D31: =COUNTIFS(Requirements!B:B,"9",Requirements!G:G,"In Progress") | E31: =COUNTIFS(Requirements!B:B,"9",Requirements!G:G,"Not Started") | F31: =COUNTIFS(Requirements!B:B,"9",Requirements!G:G,"Blocked")
A32: WS 10: Quality Release & Documentation | B32: =COUNTIF(Requirements!B:B,"10") | C32: =COUNTIFS(Requirements!B:B,"10",Requirements!G:G,"Done") | D32: =COUNTIFS(Requirements!B:B,"10",Requirements!G:G,"In Progress") | E32: =COUNTIFS(Requirements!B:B,"10",Requirements!G:G,"Not Started") | F32: =COUNTIFS(Requirements!B:B,"10",Requirements!G:G,"Blocked")
A33: WS 11: Adoption Validation & Evidence | B33: =COUNTIF(Requirements!B:B,"11") | C33: =COUNTIFS(Requirements!B:B,"11",Requirements!G:G,"Done") | D33: =COUNTIFS(Requirements!B:B,"11",Requirements!G:G,"In Progress") | E33: =COUNTIFS(Requirements!B:B,"11",Requirements!G:G,"Not Started") | F33: =COUNTIFS(Requirements!B:B,"11",Requirements!G:G,"Blocked")
A34: WS 12: Differentiation Research & IP Controls | B34: =COUNTIF(Requirements!B:B,"12") | C34: =COUNTIFS(Requirements!B:B,"12",Requirements!G:G,"Done") | D34: =COUNTIFS(Requirements!B:B,"12",Requirements!G:G,"In Progress") | E34: =COUNTIFS(Requirements!B:B,"12",Requirements!G:G,"Not Started") | F34: =COUNTIFS(Requirements!B:B,"12",Requirements!G:G,"Blocked")
A35: WS 13: License Compliance | B35: =COUNTIF(Requirements!B:B,"13") | C35: =COUNTIFS(Requirements!B:B,"13",Requirements!G:G,"Done") | D35: =COUNTIFS(Requirements!B:B,"13",Requirements!G:G,"In Progress") | E35: =COUNTIFS(Requirements!B:B,"13",Requirements!G:G,"Not Started") | F35: =COUNTIFS(Requirements!B:B,"13",Requirements!G:G,"Blocked")
A36: WS 14: Dependency Management Extended | B36: =COUNTIF(Requirements!B:B,"14") | C36: =COUNTIFS(Requirements!B:B,"14",Requirements!G:G,"Done") | D36: =COUNTIFS(Requirements!B:B,"14",Requirements!G:G,"In Progress") | E36: =COUNTIFS(Requirements!B:B,"14",Requirements!G:G,"Not Started") | F36: =COUNTIFS(Requirements!B:B,"14",Requirements!G:G,"Blocked")
A37: WS 15: Evidence Providers Extended | B37: =COUNTIF(Requirements!B:B,"15") | C37: =COUNTIFS(Requirements!B:B,"15",Requirements!G:G,"Done") | D37: =COUNTIFS(Requirements!B:B,"15",Requirements!G:G,"In Progress") | E37: =COUNTIFS(Requirements!B:B,"15",Requirements!G:G,"Not Started") | F37: =COUNTIFS(Requirements!B:B,"15",Requirements!G:G,"Blocked")
A38: WS 16: Supply Chain Defense Extended | B38: =COUNTIF(Requirements!B:B,"16") | C38: =COUNTIFS(Requirements!B:B,"16",Requirements!G:G,"Done") | D38: =COUNTIFS(Requirements!B:B,"16",Requirements!G:G,"In Progress") | E38: =COUNTIFS(Requirements!B:B,"16",Requirements!G:G,"Not Started") | F38: =COUNTIFS(Requirements!B:B,"16",Requirements!G:G,"Blocked")
A39: WS 17: Policy Engine Extended | B39: =COUNTIF(Requirements!B:B,"17") | C39: =COUNTIFS(Requirements!B:B,"17",Requirements!G:G,"Done") | D39: =COUNTIFS(Requirements!B:B,"17",Requirements!G:G,"In Progress") | E39: =COUNTIFS(Requirements!B:B,"17",Requirements!G:G,"Not Started") | F39: =COUNTIFS(Requirements!B:B,"17",Requirements!G:G,"Blocked")
A40: WS 18: Outputs & Integrations Extended | B40: =COUNTIF(Requirements!B:B,"18") | C40: =COUNTIFS(Requirements!B:B,"18",Requirements!G:G,"Done") | D40: =COUNTIFS(Requirements!B:B,"18",Requirements!G:G,"In Progress") | E40: =COUNTIFS(Requirements!B:B,"18",Requirements!G:G,"Not Started") | F40: =COUNTIFS(Requirements!B:B,"18",Requirements!G:G,"Blocked")
A41: WS 19: Quality & Compliance Extended | B41: =COUNTIF(Requirements!B:B,"19") | C41: =COUNTIFS(Requirements!B:B,"19",Requirements!G:G,"Done") | D41: =COUNTIFS(Requirements!B:B,"19",Requirements!G:G,"In Progress") | E41: =COUNTIFS(Requirements!B:B,"19",Requirements!G:G,"Not Started") | F41: =COUNTIFS(Requirements!B:B,"19",Requirements!G:G,"Blocked")
A42: WS 20: Research Extended | B42: =COUNTIF(Requirements!B:B,"20") | C42: =COUNTIFS(Requirements!B:B,"20",Requirements!G:G,"Done") | D42: =COUNTIFS(Requirements!B:B,"20",Requirements!G:G,"In Progress") | E42: =COUNTIFS(Requirements!B:B,"20",Requirements!G:G,"Not Started") | F42: =COUNTIFS(Requirements!B:B,"20",Requirements!G:G,"Blocked")

Sheet Requirements
A1: OPG ID | B1: WS# | C1: Feature Name | D1: Workstream | E1: Description / Acceptance Criteria | F1: Priority | G1: Status | H1: Implementation Notes | I1: Module / File | J1: Linked OPG IDs
A2: OPG-001 | B2: 1 | C2: Public product contract | D2: Architecture & Foundation | E2: README identifies target users, supported ecosystems, decision semantics, limitations, and five-minute quick start | F2: P0 | G2: In Progress | H2: README.md updated with product contract | I2: README.md
A3: OPG-002 | B3: 1 | C3: Safe technical-signal policy | D3: Architecture & Foundation | E3: Default score unchanged when maintainer identity/location changes; jurisdiction rules are opt-in and excluded from maliciousness inference | F3: P0 | G3: Done | H3: Safe-signal policy enforced in scoring logic | I3: oss_scorer.py
A4: OPG-003 | B4: 1 | C4: Modular package architecture | D4: Architecture & Foundation | E4: Move monolithic scorer into typed models, providers, policy, reports, manifest modules; CLI behavior and golden outputs remain compatible | F4: P0 | G4: In Progress | H4: Module skeleton created in src/osspolicyguard/ | I4: src/osspolicyguard/ | J4: OPG-005
A5: OPG-004 | B5: 1 | C5: Installable Python package | D5: Architecture & Foundation | E5: Clean Python 3.11/3.12 environment installs wheel and runs osspolicyguard --version and one offline fixture scan | F5: P0 | G5: Done | H5: pyproject.toml + src layout configured | I5: pyproject.toml
A6: OPG-005 | B6: 1 | C6: Stable public Python API | D6: Architecture & Foundation | E6: Expose documented scan_package, scan_manifest, evaluate_policy APIs with typed inputs/results and semver compatibility tests | F6: P1 | G6: In Progress | H6: scan_package() implemented; scan_manifest() stub | I6: src/osspolicyguard/cli.py | J6: OPG-003
A7: OPG-006 | B7: 1 | C7: Domain exception hierarchy | D7: Architecture & Foundation | E7: Define config, provider, identity, policy, report, and internal error types; CLI maps each to a message and exit code without traceback | F7: P0 | G7: Done | H7: Full exception hierarchy implemented | I7: src/osspolicyguard/exceptions.py
A8: OPG-007 | B8: 1 | C8: Dependency injection | D8: Architecture & Foundation | E8: Providers, clock, cache, and policy store can be injected; unit tests run without patching global requests or live network calls | F8: P0 | G8: In Progress | H8: ProviderBase ABC and NullProvider implemented | I8: src/osspolicyguard/providers/__init__.py | J8: OPG-023
A9: OPG-008 | B9: 1 | C9: Configuration layering | D9: Architecture & Foundation | E9: Merge defaults, org policy, repo policy, env vars, and CLI overrides in documented precedence; config explain shows winning source | F9: P0 | G9: In Progress | H9: Env var overrides + YAML defaults implemented | I9: oss_scorer.py / config.yaml
A10: OPG-009 | B10: 1 | C10: Configuration schema and migration | D10: Architecture & Foundation | E10: Versioned JSON Schema for YAML config; invalid keys fail with path-specific messages; older versions migrate deterministically | F10: P0 | G10: Done | H10: config.schema.json (JSON Schema draft 2020-12) | I10: config.schema.json
A11: OPG-010 | B11: 1 | C11: Structured logging | D11: Architecture & Foundation | E11: Emit JSON or human logs with request ID, package coords, provider, latency, retry count, outcome; tokens redacted in tests | F11: P1 | G11: Done | H11: RedactingFilter + StructuredFormatter implemented | I11: src/osspolicyguard/logging_config.py
A12: OPG-011 | B12: 1 | C12: Feature flag framework | D12: Architecture & Foundation | E12: Experimental providers disabled by default, named, auditable, covered by tests for enabled/disabled behavior | F12: P1 | G12: Not Started | I12: TBD
A13: OPG-012 | B13: 2 | C13: Canonical Package URL identity | D13: Identity & Dependency Ingestion | E13: Normalize every input to validated purl; equivalent spellings produce one canonical identifier | F13: P0 | G13: Done | H13: PackageUrl dataclass with per-ecosystem normalization | I13: src/osspolicyguard/identity.py
A14: OPG-013 | B14: 2 | C14: Repository resolution with confidence | D14: Identity & Dependency Ingestion | E14: Resolve package-to-repository links; report source, confidence, redirects, and ambiguity | F14: P0 | G14: In Progress | H14: GitHub URL parsing and resolution in place | I14: oss_scorer.py | J14: OPG-026
A15: OPG-014 | B15: 2 | C15: Exact version resolution | D15: Identity & Dependency Ingestion | E15: Resolve analyzed version and immutable artifact digest; reject ranges when deterministic resolution required | F15: P0 | G15: Not Started | I15: TBD | J15: OPG-012
A16: OPG-015 | B16: 2 | C16: PyPI requirements ingestion | D16: Identity & Dependency Ingestion | E16: Parse requirements.txt including pins, extras, markers, hashes, includes, constraints, editable/VCS entries | F16: P0 | G16: In Progress | H16: Basic requirements.txt scanning in CI action | I16: scripts/ | J16: OPG-012
A17: OPG-016 | B17: 2 | C17: Python lockfile ingestion | D17: Identity & Dependency Ingestion | E17: Parse Poetry, Pipenv, uv, PEP 665-compatible lock data; retain direct/transitive relationship | F17: P1 | G17: Not Started | I17: TBD | J17: OPG-015
A18: OPG-017 | B18: 2 | C18: npm manifest ingestion | D18: Identity & Dependency Ingestion | E18: Parse package.json dependency sections and workspace definitions without executing scripts; normalize scoped packages | F18: P0 | G18: In Progress | H18: Basic package.json scanning in CI action | I18: scripts/ | J18: OPG-012
A19: OPG-018 | B19: 2 | C19: npm lockfile ingestion | D19: Identity & Dependency Ingestion | E19: Support package-lock v2/v3, npm-shrinkwrap, yarn.lock, pnpm-lock; preserve resolved URL, integrity hash, depth | F19: P0 | G19: Not Started | I19: TBD | J19: OPG-017
A20: OPG-019 | B20: 2 | C20: SBOM ingestion | D20: Identity & Dependency Ingestion | E20: Accept CycloneDX 1.5+ and SPDX 2.3 JSON; validate schema and translate components to internal graph | F20: P1 | G20: Not Started | I20: TBD | J20: OPG-020
A21: OPG-020 | B21: 2 | C21: Dependency graph construction | D21: Identity & Dependency Ingestion | E21: Build deterministic directed graph with roots, direct/transitive depth, cycles, duplicates, and unresolved nodes | F21: P0 | G21: Not Started | I21: TBD | J21: OPG-012
A22: OPG-021 | B22: 2 | C22: Changed-dependency detection | D22: Identity & Dependency Ingestion | E22: Given base and head manifests/locks, identify added, removed, upgraded, downgraded, source-changed components | F22: P0 | G22: Not Started | I22: TBD | J22: OPG-020
A23: OPG-022 | B23: 2 | C23: Monorepo discovery | D23: Identity & Dependency Ingestion | E23: Discover supported manifests within configurable paths, honor ignore rules, prevent traversal outside workspace | F23: P1 | G23: Not Started | I23: TBD | J23: OPG-015,OPG-017
A24: OPG-023 | B24: 3 | C24: Provider interface contract | D24: Evidence Providers & Data Quality | E24: Every provider returns typed status, evidence, retrieval timestamp, source URL, freshness, confidence, normalized errors | F24: P0 | G24: In Progress | H24: ProviderBase + ProviderResponse contract implemented | I24: src/osspolicyguard/providers/__init__.py | J24: OPG-007
A25: OPG-024 | B25: 3 | C25: HTTP client resilience | D25: Evidence Providers & Data Quality | E25: Central client enforces connect/read timeouts, bounded retries with jitter, Retry-After, rate limits, user agent, max response size | F25: P0 | G25: In Progress | H25: Retry/backoff in ProviderBase | I25: src/osspolicyguard/providers/__init__.py | J25: OPG-023
A26: OPG-025 | B26: 3 | C26: Persistent evidence cache | D26: Evidence Providers & Data Quality | E26: Cache provider responses by normalized request and policy-relevant headers; TTL, offline mode, corruption recovery tested | F26: P0 | G26: Not Started | I26: TBD | J26: OPG-023
A27: OPG-026 | B27: 3 | C27: GitHub metadata provider | D27: Evidence Providers & Data Quality | E27: Collect repo state, activity, releases, contributors, security policy, archival status, branch protection using least-privilege auth | F27: P0 | G27: In Progress | H27: GitHubProvider implemented with caching | I27: oss_scorer.py | J27: OPG-023
A28: OPG-027 | B28: 3 | C28: OpenSSF Scorecard provider | D28: Evidence Providers & Data Quality | E28: Ingest overall and individual checks, source commit, evaluation date, unavailable status; never substitute zero for missing data | F28: P0 | G28: In Progress | H28: ScorecardProvider with enabled flag | I28: oss_scorer.py | J28: OPG-023
A29: OPG-028 | B29: 3 | C29: OSV provider | D29: Evidence Providers & Data Quality | E29: Query exact ecosystem/name/version; deduplicate aliases; retain advisory ranges, fixed versions, references, modified time | F29: P0 | G29: In Progress | H29: check_osv() with MAL-/GHSA classification | I29: oss_scorer.py | J29: OPG-040
A30: OPG-029 | B30: 3 | C30: NVD provider | D30: Evidence Providers & Data Quality | E30: Retrieve CVE, CVSS versions, CWE, CPE match rationale, publication/modification times, and rejected status | F30: P1 | G30: In Progress | H30: NVD v2 API integration with EPSS enrichment | I30: oss_scorer.py | J30: OPG-030
A31: OPG-030 | B31: 3 | C31: EPSS provider | D31: Evidence Providers & Data Quality | E31: Retrieve probability, percentile, model date, and score date for each CVE; stale or absent scores explicitly represented | F31: P0 | G31: In Progress | H31: EPSS batch enrichment per CVE list | I31: oss_scorer.py | J31: OPG-029
A32: OPG-031 | B32: 3 | C32: Registry metadata providers | D32: Evidence Providers & Data Quality | E32: PyPI and npm providers for versions, publish times, maintainers, deprecation, downloads, dist integrity | F32: P0 | G32: In Progress | H32: 7-registry download-count system implemented | I32: oss_scorer.py | J32: OPG-023
A33: OPG-032 | B33: 3 | C33: KEV and exploitation provider | D33: Evidence Providers & Data Quality | E33: Correlate CISA KEV by CVE; record catalog date, due date, ransomware flag, source | F33: P0 | G33: Done | H33: KevProvider with TTL cache | I33: src/osspolicyguard/kev.py | J33: OPG-029
A34: OPG-033 | B34: 3 | C34: Evidence conflict resolution | D34: Evidence Providers & Data Quality | E34: When providers disagree, preserve each assertion, rank authority/recency, show chosen value and rule, flag unresolved conflicts | F34: P1 | G34: Not Started | I34: TBD | J34: OPG-023
A35: OPG-034 | B35: 4 | C35: Version-aware vulnerability matching | D35: Vulnerability & Exploitability | E35: Match advisories to exact resolved versions using ecosystem semantics; boundary, prerelease, epoch tests prevent false matches | F35: P0 | G35: Not Started | I35: TBD | J35: OPG-012,OPG-028
A36: OPG-035 | B36: 4 | C36: Reachability evidence model | D36: Vulnerability & Exploitability | E36: Represent confirmed, likely, unknown, unreachable paths with method and evidence; unknown never becomes unreachable by default | F36: P1 | G36: Not Started | I36: TBD | J36: OPG-020
A37: OPG-036 | B37: 4 | C37: VEX support | D37: Vulnerability & Exploitability | E37: Ingest CycloneDX and CSAF/OpenVEX statements, validate signer/issuer policy, respect expiry, retain justification | F37: P1 | G37: Not Started | I37: TBD | J37: OPG-028
A38: OPG-037 | B38: 4 | C38: Exploitability-adjusted severity | D38: Vulnerability & Exploitability | E38: Compute documented risk contribution using CVSS, EPSS, KEV, reachability, exposure, criticality; each factor in explanation | F38: P0 | G38: Not Started | I38: TBD | J38: OPG-029,OPG-030,OPG-032
A39: OPG-038 | B39: 4 | C39: Fix availability analysis | D39: Vulnerability & Exploitability | E39: Report first fixed version, safe upgrade candidates, breaking-change boundary, and no-fix status | F39: P0 | G39: Not Started | I39: TBD | J39: OPG-034
A40: OPG-039 | B40: 4 | C40: Vulnerability aging | D40: Vulnerability & Exploitability | E40: Calculate time since publication, fix availability, policy SLA breach using injected clock; timezone and future-date tested | F40: P1 | G40: Not Started | I40: TBD | J40: OPG-034
...

Sheet Workstream Summary
A1: Workstream Summary
A2: WS # | B2: Name | C2: Total | D2: P0 | E2: P1 | F2: P2 | G2: Done | H2: In Progress | I2: Not Started
A3: 1 | B3: Architecture & Foundation | C3: =COUNTIF(Requirements!B:B,"1") | D3: =COUNTIFS(Requirements!B:B,"1",Requirements!F:F,"P0") | E3: =COUNTIFS(Requirements!B:B,"1",Requirements!F:F,"P1") | F3: =COUNTIFS(Requirements!B:B,"1",Requirements!F:F,"P2") | G3: =COUNTIFS(Requirements!B:B,"1",Requirements!G:G,"Done") | H3: =COUNTIFS(Requirements!B:B,"1",Requirements!G:G,"In Progress") | I3: =COUNTIFS(Requirements!B:B,"1",Requirements!G:G,"Not Started")
A4: 2 | B4: Identity & Dependency Ingestion | C4: =COUNTIF(Requirements!B:B,"2") | D4: =COUNTIFS(Requirements!B:B,"2",Requirements!F:F,"P0") | E4: =COUNTIFS(Requirements!B:B,"2",Requirements!F:F,"P1") | F4: =COUNTIFS(Requirements!B:B,"2",Requirements!F:F,"P2") | G4: =COUNTIFS(Requirements!B:B,"2",Requirements!G:G,"Done") | H4: =COUNTIFS(Requirements!B:B,"2",Requirements!G:G,"In Progress") | I4: =COUNTIFS(Requirements!B:B,"2",Requirements!G:G,"Not Started")
A5: 3 | B5: Evidence Providers & Data Quality | C5: =COUNTIF(Requirements!B:B,"3") | D5: =COUNTIFS(Requirements!B:B,"3",Requirements!F:F,"P0") | E5: =COUNTIFS(Requirements!B:B,"3",Requirements!F:F,"P1") | F5: =COUNTIFS(Requirements!B:B,"3",Requirements!F:F,"P2") | G5: =COUNTIFS(Requirements!B:B,"3",Requirements!G:G,"Done") | H5: =COUNTIFS(Requirements!B:B,"3",Requirements!G:G,"In Progress") | I5: =COUNTIFS(Requirements!B:B,"3",Requirements!G:G,"Not Started")
A6: 4 | B6: Vulnerability & Exploitability | C6: =COUNTIF(Requirements!B:B,"4") | D6: =COUNTIFS(Requirements!B:B,"4",Requirements!F:F,"P0") | E6: =COUNTIFS(Requirements!B:B,"4",Requirements!F:F,"P1") | F6: =COUNTIFS(Requirements!B:B,"4",Requirements!F:F,"P2") | G6: =COUNTIFS(Requirements!B:B,"4",Requirements!G:G,"Done") | H6: =COUNTIFS(Requirements!B:B,"4",Requirements!G:G,"In Progress") | I6: =COUNTIFS(Requirements!B:B,"4",Requirements!G:G,"Not Started")
A7: 5 | B7: Supply Chain & Malicious Package Defense | C7: =COUNTIF(Requirements!B:B,"5") | D7: =COUNTIFS(Requirements!B:B,"5",Requirements!F:F,"P0") | E7: =COUNTIFS(Requirements!B:B,"5",Requirements!F:F,"P1") | F7: =COUNTIFS(Requirements!B:B,"5",Requirements!F:F,"P2") | G7: =COUNTIFS(Requirements!B:B,"5",Requirements!G:G,"Done") | H7: =COUNTIFS(Requirements!B:B,"5",Requirements!G:G,"In Progress") | I7: =COUNTIFS(Requirements!B:B,"5",Requirements!G:G,"Not Started")
A8: 6 | B8: Policy Engine & Explainability | C8: =COUNTIF(Requirements!B:B,"6") | D8: =COUNTIFS(Requirements!B:B,"6",Requirements!F:F,"P0") | E8: =COUNTIFS(Requirements!B:B,"6",Requirements!F:F,"P1") | F8: =COUNTIFS(Requirements!B:B,"6",Requirements!F:F,"P2") | G8: =COUNTIFS(Requirements!B:B,"6",Requirements!G:G,"Done") | H8: =COUNTIFS(Requirements!B:B,"6",Requirements!G:G,"In Progress") | I8: =COUNTIFS(Requirements!B:B,"6",Requirements!G:G,"Not Started")
A9: 7 | B9: Outputs APIs & Developer Integrations | C9: =COUNTIF(Requirements!B:B,"7") | D9: =COUNTIFS(Requirements!B:B,"7",Requirements!F:F,"P0") | E9: =COUNTIFS(Requirements!B:B,"7",Requirements!F:F,"P1") | F9: =COUNTIFS(Requirements!B:B,"7",Requirements!F:F,"P2") | G9: =COUNTIFS(Requirements!B:B,"7",Requirements!G:G,"Done") | H9: =COUNTIFS(Requirements!B:B,"7",Requirements!G:G,"In Progress") | I9: =COUNTIFS(Requirements!B:B,"7",Requirements!G:G,"Not Started")
A10: 8 | B10: Enterprise Governance & Exceptions | C10: =COUNTIF(Requirements!B:B,"8") | D10: =COUNTIFS(Requirements!B:B,"8",Requirements!F:F,"P0") | E10: =COUNTIFS(Requirements!B:B,"8",Requirements!F:F,"P1") | F10: =COUNTIFS(Requirements!B:B,"8",Requirements!F:F,"P2") | G10: =COUNTIFS(Requirements!B:B,"8",Requirements!G:G,"Done") | H10: =COUNTIFS(Requirements!B:B,"8",Requirements!G:G,"In Progress") | I10: =COUNTIFS(Requirements!B:B,"8",Requirements!G:G,"Not Started")
A11: 9 | B11: Security Privacy & Reliability | C11: =COUNTIF(Requirements!B:B,"9") | D11: =COUNTIFS(Requirements!B:B,"9",Requirements!F:F,"P0") | E11: =COUNTIFS(Requirements!B:B,"9",Requirements!F:F,"P1") | F11: =COUNTIFS(Requirements!B:B,"9",Requirements!F:F,"P2") | G11: =COUNTIFS(Requirements!B:B,"9",Requirements!G:G,"Done") | H11: =COUNTIFS(Requirements!B:B,"9",Requirements!G:G,"In Progress") | I11: =COUNTIFS(Requirements!B:B,"9",Requirements!G:G,"Not Started")
A12: 10 | B12: Quality Release & Documentation | C12: =COUNTIF(Requirements!B:B,"10") | D12: =COUNTIFS(Requirements!B:B,"10",Requirements!F:F,"P0") | E12: =COUNTIFS(Requirements!B:B,"10",Requirements!F:F,"P1") | F12: =COUNTIFS(Requirements!B:B,"10",Requirements!F:F,"P2") | G12: =COUNTIFS(Requirements!B:B,"10",Requirements!G:G,"Done") | H12: =COUNTIFS(Requirements!B:B,"10",Requirements!G:G,"In Progress") | I12: =COUNTIFS(Requirements!B:B,"10",Requirements!G:G,"Not Started")
A13: 11 | B13: Adoption Validation & Evidence | C13: =COUNTIF(Requirements!B:B,"11") | D13: =COUNTIFS(Requirements!B:B,"11",Requirements!F:F,"P0") | E13: =COUNTIFS(Requirements!B:B,"11",Requirements!F:F,"P1") | F13: =COUNTIFS(Requirements!B:B,"11",Requirements!F:F,"P2") | G13: =COUNTIFS(Requirements!B:B,"11",Requirements!G:G,"Done") | H13: =COUNTIFS(Requirements!B:B,"11",Requirements!G:G,"In Progress") | I13: =COUNTIFS(Requirements!B:B,"11",Requirements!G:G,"Not Started")
A14: 12 | B14: Differentiation Research & IP Controls | C14: =COUNTIF(Requirements!B:B,"12") | D14: =COUNTIFS(Requirements!B:B,"12",Requirements!F:F,"P0") | E14: =COUNTIFS(Requirements!B:B,"12",Requirements!F:F,"P1") | F14: =COUNTIFS(Requirements!B:B,"12",Requirements!F:F,"P2") | G14: =COUNTIFS(Requirements!B:B,"12",Requirements!G:G,"Done") | H14: =COUNTIFS(Requirements!B:B,"12",Requirements!G:G,"In Progress") | I14: =COUNTIFS(Requirements!B:B,"12",Requirements!G:G,"Not Started")
A15: 13 | B15: License Compliance | C15: =COUNTIF(Requirements!B:B,"13") | D15: =COUNTIFS(Requirements!B:B,"13",Requirements!F:F,"P0") | E15: =COUNTIFS(Requirements!B:B,"13",Requirements!F:F,"P1") | F15: =COUNTIFS(Requirements!B:B,"13",Requirements!F:F,"P2") | G15: =COUNTIFS(Requirements!B:B,"13",Requirements!G:G,"Done") | H15: =COUNTIFS(Requirements!B:B,"13",Requirements!G:G,"In Progress") | I15: =COUNTIFS(Requirements!B:B,"13",Requirements!G:G,"Not Started")
A16: 14 | B16: Dependency Management Extended | C16: =COUNTIF(Requirements!B:B,"14") | D16: =COUNTIFS(Requirements!B:B,"14",Requirements!F:F,"P0") | E16: =COUNTIFS(Requirements!B:B,"14",Requirements!F:F,"P1") | F16: =COUNTIFS(Requirements!B:B,"14",Requirements!F:F,"P2") | G16: =COUNTIFS(Requirements!B:B,"14",Requirements!G:G,"Done") | H16: =COUNTIFS(Requirements!B:B,"14",Requirements!G:G,"In Progress") | I16: =COUNTIFS(Requirements!B:B,"14",Requirements!G:G,"Not Started")
A17: 15 | B17: Evidence Providers Extended | C17: =COUNTIF(Requirements!B:B,"15") | D17: =COUNTIFS(Requirements!B:B,"15",Requirements!F:F,"P0") | E17: =COUNTIFS(Requirements!B:B,"15",Requirements!F:F,"P1") | F17: =COUNTIFS(Requirements!B:B,"15",Requirements!F:F,"P2") | G17: =COUNTIFS(Requirements!B:B,"15",Requirements!G:G,"Done") | H17: =COUNTIFS(Requirements!B:B,"15",Requirements!G:G,"In Progress") | I17: =COUNTIFS(Requirements!B:B,"15",Requirements!G:G,"Not Started")
A18: 16 | B18: Supply Chain Defense Extended | C18: =COUNTIF(Requirements!B:B,"16") | D18: =COUNTIFS(Requirements!B:B,"16",Requirements!F:F,"P0") | E18: =COUNTIFS(Requirements!B:B,"16",Requirements!F:F,"P1") | F18: =COUNTIFS(Requirements!B:B,"16",Requirements!F:F,"P2") | G18: =COUNTIFS(Requirements!B:B,"16",Requirements!G:G,"Done") | H18: =COUNTIFS(Requirements!B:B,"16",Requirements!G:G,"In Progress") | I18: =COUNTIFS(Requirements!B:B,"16",Requirements!G:G,"Not Started")
A19: 17 | B19: Policy Engine Extended | C19: =COUNTIF(Requirements!B:B,"17") | D19: =COUNTIFS(Requirements!B:B,"17",Requirements!F:F,"P0") | E19: =COUNTIFS(Requirements!B:B,"17",Requirements!F:F,"P1") | F19: =COUNTIFS(Requirements!B:B,"17",Requirements!F:F,"P2") | G19: =COUNTIFS(Requirements!B:B,"17",Requirements!G:G,"Done") | H19: =COUNTIFS(Requirements!B:B,"17",Requirements!G:G,"In Progress") | I19: =COUNTIFS(Requirements!B:B,"17",Requirements!G:G,"Not Started")
A20: 18 | B20: Outputs & Integrations Extended | C20: =COUNTIF(Requirements!B:B,"18") | D20: =COUNTIFS(Requirements!B:B,"18",Requirements!F:F,"P0") | E20: =COUNTIFS(Requirements!B:B,"18",Requirements!F:F,"P1") | F20: =COUNTIFS(Requirements!B:B,"18",Requirements!F:F,"P2") | G20: =COUNTIFS(Requirements!B:B,"18",Requirements!G:G,"Done") | H20: =COUNTIFS(Requirements!B:B,"18",Requirements!G:G,"In Progress") | I20: =COUNTIFS(Requirements!B:B,"18",Requirements!G:G,"Not Started")
A21: 19 | B21: Quality & Compliance Extended | C21: =COUNTIF(Requirements!B:B,"19") | D21: =COUNTIFS(Requirements!B:B,"19",Requirements!F:F,"P0") | E21: =COUNTIFS(Requirements!B:B,"19",Requirements!F:F,"P1") | F21: =COUNTIFS(Requirements!B:B,"19",Requirements!F:F,"P2") | G21: =COUNTIFS(Requirements!B:B,"19",Requirements!G:G,"Done") | H21: =COUNTIFS(Requirements!B:B,"19",Requirements!G:G,"In Progress") | I21: =COUNTIFS(Requirements!B:B,"19",Requirements!G:G,"Not Started")
A22: 20 | B22: Research Extended | C22: =COUNTIF(Requirements!B:B,"20") | D22: =COUNTIFS(Requirements!B:B,"20",Requirements!F:F,"P0") | E22: =COUNTIFS(Requirements!B:B,"20",Requirements!F:F,"P1") | F22: =COUNTIFS(Requirements!B:B,"20",Requirements!F:F,"P2") | G22: =COUNTIFS(Requirements!B:B,"20",Requirements!G:G,"Done") | H22: =COUNTIFS(Requirements!B:B,"20",Requirements!G:G,"In Progress") | I22: =COUNTIFS(Requirements!B:B,"20",Requirements!G:G,"Not Started")
A23: TOTAL | C23: =SUM(C3:C22) | D23: =SUM(D3:D22) | E23: =SUM(E3:E22) | F23: =SUM(F3:F22) | G23: =SUM(G3:G22) | H23: =SUM(H3:H22) | I23: =SUM(I3:I22)

Sheet Roadmap
A1: OSSPolicyGuard — Delivery Roadmap
A2: Phase | B2: Timeframe | C2: Focus | D2: Key Requirements | E2: Success Criteria
A3: Phase 1 — Foundation | B3: Current | C3: Core scanning engine and CLI | D3: OPG-001–011, OPG-023–032, OPG-056–072 | E3: All P0 foundation requirements done; 200+ tests
A4: Phase 2 — Hardening | B4: Q4 2025 | C4: Security, compliance, quality | D4: OPG-034–053, OPG-089–107 | E4: Zero untrusted-input vulnerabilities; SARIF in GitHub Code Scanning
A5: Phase 3 — Enterprise | B5: Q1 2026 | C5: Governance and integrations | D5: OPG-073–088, OPG-133–153 | E5: License compliance; SBOM output; exception workflow; audit log
A6: Phase 4 — Scale | B6: Q2 2026 | C6: Adoption and pilots | D6: OPG-111–121 | E6: 5 independent pilots; benchmark published
A7: Phase 5 — Research | B7: Q3 2026 | C7: Differentiation research | D7: OPG-122–132, OPG-154–157 | E7: 2+ research contributions submitted
A9: Phases are indicative and subject to revision based on pilot feedback and resource availability.
